Workbook

Sheet Schedule
A1: Sr No. | B1: Vendor Code | C1: Erp Id | D1: Zone | E1: State | F1: Location | G1: Agency Type | H1: Vendor Name | I1: Owner/Partners/Director's Name | J1: Contact Person | K1: Address | L1: Office Phone # | M1: YBL collection contact | N1: Owner Phone # | O1: EMail ID | P1: Alternate Email Id | Q1: PAN No | R1: Service Tax No | S1: GST no | T1: ARN Number | U1: YBL A/c No | V1: BANK_NAME | W1: YBL A/c Status | X1: Category | Y1: Status | Z1: Agreement Date (DD/MM/YYYY) | AA1: ORM/BH Approval (DD/MM/YYYY) | AB1: Discontinued/ Termination Date (DD/MM/YYYY) | AC1: Discontinued/Termination Reason | AD1: Remarks | AE1: ERP ID | AF1: Vendor Name | AG1: JAN'26 | AH1: FEB'26 | AI1: MAR'26 | AJ1: Total | AK1: As per Repo Tracker | AL1: Eligible Reason | AM1: Eligible Status | AN1: Audit Firm | AO1: RCM Name | AP1: Audited address | AQ1: Status | AR1: Remarks | AS1: Console | AT1: Manager | AU1: Auditor Name | AV1: Auditor Cont. Number | AW1: Audit date | AX1: Vendor Name | AY1: Location | AZ1: State | BA1: CM ID | BB1: CM | BC1: RCM | BD1: Vendor Name | BE1: File Name | BF1: Collection Agency | BG1: Repo Agency
A2: 1 | B2: 66907 | C2: 66907 | D2: East | E2: Assam | F2: Guwahati | G2: Collection & Repossession Agency | H2: Aba | I2: Junti Bania | J2: Junti Bania | K2: House No -33, Rangmili Path, M T Road, Guwahati - 780124 | L2: 8638990389,7002339398 | M2: 8638990389,7002339398 | N2: 8638990389,7002339398 | O2: aba.guwahati002@gmail.com, northeast@abaguwahati.Co.in | P2: NA | Q2: AXUPB5259R | S2: 18AXUPB5259R1ZG | V2: YES BANK LIMITED | X2: Properitoryship | Y2: Active | Z2: 45197 | AA2: 45195 | AE2: 66907 | AF2: ABA | AG2: 244 | AH2: 267 | AI2: 279 | AJ2: 790 | AL2: Allocaton given by Collection agency | AM2: Eligible for audit | AN2: KGAC | AO2: Md Shabbir Alam | AP2: 3 Rd Florr House No 20 Hr Port Near Decora Marriage Hall Rgb Road Guwahati | AQ2: Audited | AR2: NA | AT2: Abdul Kayum | AU2: Pradeep | AV2: 8287823681 | AW2: 46130 | AX2: Kumar Gaurav Agarwal & company | AY2: Guwahati | AZ2: Assam | BA2: BKE6757902, GCE6775573 | BB2: Bikash Kalita, Gautam Chowdhury | BC2: Subhasis Banerjee, Md Shabbir Alam | BD2: Aba | BE2: Aba - Guwahati - Assam | BF2: Aba_Collection Agency_Guwahati_Assam
A3: 2 | B3: Z20583 | C3: 26018 | D3: East | E3: Assam | F3: Guwahati | G3: Collection & Repossession Agency | H3: Fairadvisory Legalservices | I3: Nidhi Prakash Yadav | J3: Nidhi Prakash Yadav | K3: H No .4 Dispur Gate Naharani Path Guwahati Assam 781038 | L3: 0657-2438714 | M3: 0657-2438714,8521158806,7677437282,7978942486,7504735768,9861236045,6901459251,9934824866,9864030986,7061093255, 8210106510, 8210106510, 7338703469, 8610129493, 8754312805, 9087498198, 9360441597, 9952066494, | N3: 9031040500 | O3: fairadvisory.jsr@gmail.com; collection@fairadvisory.net.in | P3: nidhi_kgdn@rediffmail.com | Q3: AAPPY5351B | S3: 20AAPPY5351B1ZS | V3: YES BANK LIMITED | X3: Properitoryship | Y3: Active | Z3: 43297 | AA3: 43297 | AD3: New email id registeration request received in Jul, Repo activity added in Dec | AE3: 26018 | AF3: Fairadvisory Legalservices | AG3: 1762 | AH3: 1483 | AI3: 1338 | AJ3: 4583 | AK3: 5 | AL3: Allocaton given by Collection & Repossession | AM3: Eligible for audit | AN3: KGAC | AO3: Biswarup Ghosh | AP3: NA | AQ3: Not Audited | AR3: Visited the agency but audit not done due to agency is working for Yes Bank from their another branch, Address : 454, Urao Basti, Old Sitaramdera, P.O - Agrico, Jamshedpur - 831009 | AS3: NA | AT3: NA | AU3: NA | AV3: NA | AW3: NA | AX3: NA | AY3: Guwahati | AZ3: Assam | BA3: PSE6778569, JSE6785583, PYE6778749, NKE6776587, SDE6778568, SSE6756265, NDE6765957, STE6769262, SBE5788018 | BB3: Pravesh Sharma, Jay Shukla, Pankaj Yadav, Nitumani Kalita, Suman Das, Santosh Sharmayanjyoti Deka, Santosh Thakur, Sachin Bharti | BC3: Biswarup Ghosh, Md Shabbir Alam | BD3: Fairadvisory Legalservices | BE3: NA | BF3: NA | BG3: NA
A4: 119 | B4: NA | C4: 185979 | D4: North | E4: Delhi | F4: Delhi | G4: Collection Agency | H4: Accurate Investigations | I4: Daya Nand Kaushik | J4: Daya Nand Kaushik | K4: A5- Shankar Garden Opp Metro Pillar No 618, Najafgarh Road Vikas Puri New Delhi 110018 | L4: 9873412356 , 7217773183 | M4: 9873412356 , 7217773183 | N4: 9873412356 , 7217773183 | O4: dayanand.kaushik1972@gmail.com ; veenu.1976@gmail.com ; recon@accurateinvestigations.in | P4: NA | Q4: ASZPK5551F | S4: 07ASZPK5551F1Z9 | X4: Properitoryship | Y4: Active | Z4: 45996 | AA4: 45996 | AD4: Supplementary done on 5th Dec 25 | AE4: 185979 | AF4: ACCURATE INVESTIGATIONS | AG4: 248 | AH4: 586 | AI4: 695 | AJ4: 1529 | AL4: Allocaton given by Collection agency | AM4: Eligible for audit | AN4: KGAC | AO4: NA | AP4: A5- Shankar Garden Opp Metro Pillar No 618, Najafgarh Road Vikas Puri New Delhi 110018 | AQ4: Audited | AR4: NA | AT4: Pravesh (9205533109) | AU4: Parteek Yadav | AV4: 7460008081 | AW4: 46120 | AX4: Kumar Gaurav Agarwal & company | AY4: Delhi | AZ4: Delhi | BA4: VGE6773224, SRE6782838, NKE6775741, JSE6785583, SBE6782270 | BB4: Vishal Gupta, Sidharth RaNitin Kumar, Jay Shukla, Subhajit Bhowmik | BC4: Na | BD4: Accurate Investigations | BE4: Accurate Investigations - Delhi | BF4: Accurate Investigations_Collection Agency_Delhi
A5: 179 | B5: NA | C5: 351028 | D5: North | E5: Uttar Pradesh | F5: Lucknow | G5: Repossession Agency | H5: Aarya Associates | I5: Vijender Singh | J5: Vijender Singh | K5: Flat No.210,Skyline-3 Sushant Golf City Ansal Api Lucknow Uttar Pradesh-226030 | L5: 7070007010 | M5: 7070007010 | N5: 7070007010 | O5: aarya.repo2014@gmail.com | P5: NA | Q5: CDEPS6081E | S5: 09CDEPS6081E1ZA | X5: Proprietorship | Y5: Active | Z5: 45835 | AA5: 45834 | AE5: 351028 | AF5: AARYA ASSOCIATES | AG5: NA | AH5: NA | AI5: NA | AJ5: NA | AK5: 10 | AL5: Allocaton given by Repo agency | AM5: Eligible for audit | AN5: KGAC | AO5: #N/A | AP5: Flat No.210,Skyline-3 Sushant Golf City Ansal Api Lucknow Uttar Pradesh-226030 | AQ5: Audited | AR5: NA | AT5: Aaditya Gupta : 8931845182 | AU5: Hariom Sharma | AV5: 9810670823 | AW5: 46125 | AX5: Kumar Gaurav Agarwal & company | AY5: Lucknow | AZ5: Uttar Pradesh | BA5: NA | BB5: Shyam Parkash, Rittin Arya, Vivek Shukla, Vivek Kumar Shukla | BC5: Sameer Dhar, Abhinav Lal, Sanjeev Kumar | BD5: Aarya Associates | BE5: Aarya Associates - Lucknow - Uttar Pradesh | BF5: Aarya Associates_Collection Agency_Lucknow_Uttar Pradesh | BG5: Aarya Associates_Repo Agency_Lucknow_Uttar Pradesh
A6: 84 | B6: Z15138 | C6: 26225 | D6: North | E6: Uttar Pradesh | F6: Kanpur | G6: Collection & Repossession Agency | H6: Agpo Management Services Pvt Ltd - Kanpur | I6: Gaurav Agrawal | J6: Gaurav Agrawal | K6: 2Nd Floor, 111/273 Harsh Nagar,Kanpur 208012 | L6: 0522-4958979,9839068693,0512-2540019,0562-4000125,0522-4622891 | M6: 0522-4958979,9839068693,0512-2540019,0562-4000125,8869880805,7080800310,7905710207,9335905751,9720123148,9198779911,9044015935,7800029105,9359051896,9161544560,9026110389,8588918415,7080329092,8868065575,0522-4622891 | N6: 0512-3016879 | O6: YESBANKAGPO@GMAIL.COM | P6: NA | Q6: AAECA4088K | S6: 09AAECA4088K1ZB | V6: ICICI BANK LIMITED | X6: PVT Ltd | Y6: Active | Z6: 43115 | AA6: 43066 | AE6: 26225 | AF6: Agpo Management Services Pvt Ltd | AG6: 1602 | AH6: 1715 | AI6: 2033 | AJ6: 5350 | AK6: 9 | AL6: Allocaton given by Collection & Repossession | AM6: Eligible for audit | AN6: KGAC | AO6: Abhinav Lal | AP6: 2Nd Floor, 111/273 Harsh Nagar,Kanpur 208012 | AQ6: Audited | AR6: Audited for Collection Only, as no activity of repossession are done from Kanpur branch | AT6: Md Imran | AU6: Chandan Sharma | AV6: 7753851136 | AW6: 46123 | AX6: Kumar Gaurav Agarwal & company | AY6: Kanpur | AZ6: Uttar Pradesh | BA6: VME6772902, SPE6785038, SCE6722048, SKE6774754, APE6750911, RSE6763776, NSE6773411, RHE6775503, HJE6739606, DAE6777331, VGE6786972, PKE6749748 | BB6: Vaibhav Mishra, Shashi Pratap Singh, Sachin Chauhan, Satendra Kumar, Amit Pandey, Ram Shankar, Nitin Srivastava, Rahul Harishankar, Harish Johar, Devendra AsthaVivek Gupta, Pawan Kumar | BC6: Sameer Dhar, Sanjeev Kumar, Abhinav Lal, Subhodip Mukherjee, Vineet Kumar | BD6: Agpo Management Services Pvt Ltd - Kanpur | BE6: Agpo Management Services Pvt Ltd - Kanpur - Uttar Pradesh | BF6: Agpo Management Services Pvt Ltd - Kanpur_Collection Agency_Uttar Pradesh
A7: 6 | B7: Z20543 | C7: 25557 | D7: East | E7: Assam | F7: Siliguri | G7: Collection & Repossession Agency | H7: Aim Corporate | I7: Sanjay Gupta | J7: Sanjay Gupta/Suresh Bisoi | K7: 102 Ramkrishna Raod,Ashrampara, Pin-734001,Word No-14, Siliguri,West Bengal | L7: 86480,30702,9007374460,9874289876,7595900524 | M7: 86480,30702,9007374460,9836763581,7044067822,9051761080,8697789378,8296720891,6290612984,8910991842,9804445016,9038223935,9874930018,9874289876,7980165338,9832055052,7001938434,7000482645,9098301963,8240590554,9002842557,8319378592,7718236167,8777381034,9977401420,9826122732,9062106927,7595900524,9830343106 | N7: 8697564337 | O7: collections5@aimcorporate.co | P7: NA | Q7: AVBPG1374M | S7: 19AVBPG1374M2ZD | V7: YES BANK LIMITED | X7: Properitoryship | Y7: Active | Z7: 43283 | AA7: 43281 | AD7: Repo activity added in Dec 21,Email id change req recd on 14th Jun. Supplementary agreement added for Jamshedpur Bhubaneshwar on 3rd Aug'22 | AE7: 25557 | AF7: Aim Corporate | AG7: 1287 | AH7: 1305 | AI7: 1328 | AJ7: 3920 | AK7: 16 | AL7: Allocaton given by Collection & Repossession | AM7: Eligible for audit | AN7: KGAC | AO7: Biswarup Ghosh | AP7: NA | AQ7: Not Audited | AR7: Visited the agency but audit not done due to agency is working for Yes Bank from their another branch, Address : 17/3 Sahapur Colony New Alipore, Kolkata-700053 | AS7: NA | AT7: NA | AU7: NA | AV7: NA | AW7: NA | AX7: NA | AY7: Siliguri | AZ7: Assam | BA7: KSE6767729, SME6784348, IEE6769906, PME6771779, RBE6757282, DSE6782069, SNE6610031, ASE6777499, TSE6288042, NKE6754736, RHE6158002, ABE6771337, OAE6762281, SGE6696032, MAE6785142, JME6788432 | BB7: Krishnendu Sarder, Saisab Mallick, Imran Elahi, Priyanka Mondal, Ritam Basak, Deepak Singh, Suryanarayan Nayak, Arindam Sarkar, Tarkeshwar Singh, Nishant Kumar, Rajkumar Hazra, Abhisek Bose, Ossam Aditya, Soumitra Ghosh, Monawwar Alam, Jayadev Mishra | BC7: Subhasis Banerjee, Biswarup Ghosh, Md Shabbir Alam | BD7: Aim Corporate | BE7: NA | BF7: NA | BG7: NA
A8: 86 | B8: Z15138 | C8: 26225 | D8: North | E8: Uttar Pradesh | F8: Lucknow | G8: Collection & Repossession Agency | H8: Agpo Management Services Pvt Ltd - Lucknow | I8: Gaurav Agrawal | J8: Gaurav Agrawal | K8: 2Nd Floor, Seth Sadan Compund, 20 Rana Pratap Marg, Lucknow, - 226001- | L8: 0522-4958979,9839068693,0512-2540019,0562-4000125,0522-4622891 | M8: 0522-4958979,9839068693,0512-2540019,0562-4000125,8869880805,7080800310,7905710207,9335905751,9720123148,9198779911,9044015935,7800029105,9359051896,9161544560,9026110389,8588918415,7080329092,8868065575,0522-4622891 | N8: 0512-3016879 | O8: YESBANKAGPO@GMAIL.COM | P8: NA | Q8: AAECA4088K | S8: 09AAECA4088K1ZB | V8: ICICI BANK LIMITED | X8: PVT Ltd | Y8: Active | Z8: 43115 | AA8: 43066 | AE8: 26225 | AF8: Agpo Management Services Pvt Ltd | AG8: 1602 | AH8: 1715 | AI8: 2033 | AJ8: 5350 | AK8: 9 | AL8: Allocaton given by Collection & Repossession | AM8: Eligible for audit | AN8: KGAC | AP8: 2Nd Floor, Seth Sadan Compund, 20 Rana Pratap Marg, Lucknow, - 226001- | AQ8: Audited | AR8: Audited for Collection Only, as no activity of repossession are done from Lucknow branch | AT8: Arvind Kumar Mishra : 7080800310 | AU8: Hariom Sharma | AV8: 9810670823 | AW8: 46126 | AX8: Kumar Gaurav Agarwal & company | AY8: Lucknow | AZ8: Uttar Pradesh | BA8: VME6772902, SPE6785038, SCE6722048, SKE6774754, APE6750911, RSE6763776, NSE6773411, RHE6775503, HJE6739606, DAE6777331, VGE6786972, PKE6749748 | BB8: Vaibhav Mishra, Shashi Pratap Singh, Sachin Chauhan, Satendra Kumar, Amit Pandey, Ram Shankar, Nitin Srivastava, Rahul Harishankar, Harish Johar, Devendra AsthaVivek Gupta, Pawan Kumar | BC8: Sameer Dhar, Sanjeev Kumar, Abhinav Lal, Subhodip Mukherjee, Vineet Kumar | BD8: Agpo Management Services Pvt Ltd - Lucknow | BE8: Agpo Management Services Pvt Ltd - Lucknow - Uttar Pradesh | BF8: Agpo Management Services Pvt Ltd - Lucknow_Collection Agency_Uttar Pradesh
A9: 37 | B9: NA | C9: 348998 | D9: North | E9: Delhi | F9: Delhi | G9: Collection & Repossession Agency | H9: Aim Associates | I9: Sanjay Sethi | J9: Sanjay Sethi | K9: 45-46 Balaji Complex, 2Nd Floor, Guru Nanak Nagar West Laxmi Nagar New Delhi 110092 | L9: 01146142871, 43702304 | M9: 01146142871, 43702304 | N9: 9811006913 | O9: ysethi@aimsanjay.com | P9: NA | Q9: ALJPS1500R | S9: 07ALJPS1500R1ZP | V9: ICICI BANK LIMITED | X9: Proprietorship | Y9: Active | Z9: 45838 | AA9: 45838 | AE9: 348998 | AF9: Aim Associates | AG9: 172 | AH9: 181 | AI9: 138 | AJ9: 491 | AL9: Allocaton given by Collection agency | AM9: Eligible for audit | AN9: KGAC | AO9: Sameer Dhar | AP9: 45-46 Balaji Complex, 2Nd Floor, Guru Nanak Nagar West Laxmi Nagar New Delhi 110092 | AQ9: Audited | AR9: NA | AT9: Sanjay Sethi /9811006913 | AU9: Abhinav Khurana | AV9: 9217935065 | AW9: 46123 | AX9: Kumar Gaurav Agarwal & company | AY9: Delhi | AZ9: Delhi | BA9: PGE6777921, NSE6771909 | BB9: Priyanka Guptarinder Singh | BC9: Sameer Dhar, Sanjeev Kumar | BD9: Aim Associates | BE9: Aim Associates - Delhi | BF9: Aim Associates_Collection Agency_Delhi
A10: 80 | B10: Z15138 | C10: 26225 | D10: North | E10: Uttar Pradesh | F10: Agra | G10: Collection & Repossession Agency | H10: Agpo Management Services Pvt Ltd - Agra | I10: Gaurav Agrawal | J10: Gaurav Agrawal | K10: Shop No 14, 2Nd Floor, Block No 1, Shoe Market, Sanjay Place, Agra - 282002- | L10: 0522-4958979,9839068693,0512-2540019,0562-4000125,0522-4622891 | M10: 0522-4958979,9839068693,0512-2540019,0562-4000125,8869880805,7080800310,7905710207,9335905751,9720123148,9198779911,9044015935,7800029105,9359051896,9161544560,9026110389,8588918415,7080329092,8868065575,0522-4622891 | N10: 0512-3016879 | O10: YESBANKAGPO@GMAIL.COM | P10: NA | Q10: AAECA4088K | S10: 09AAECA4088K1ZB | V10: ICICI BANK LIMITED | X10: PVT Ltd | Y10: Active | Z10: 43115 | AA10: 43066 | AE10: 26225 | AF10: Agpo Management Services Pvt Ltd | AG10: 1602 | AH10: 1715 | AI10: 2033 | AJ10: 5350 | AK10: 9 | AL10: Allocaton given by Collection & Repossession | AM10: Eligible for audit | AN10: KGAC | AP10: Shop No 14, 2Nd Floor, Block No 1, Shoe Market, Sanjay Place, Agra - 282002- | AQ10: Audited | AR10: NA | AT10: Ram Kumar | AU10: Chandan Sharma | AV10: 7753851136 | AW10: 46127 | AX10: Kumar Gaurav Agarwal & company | AY10: Agra | AZ10: Uttar Pradesh | BA10: VME6772902, SPE6785038, SCE6722048, SKE6774754, APE6750911, RSE6763776, NSE6773411, RHE6775503, HJE6739606, DAE6777331, VGE6786972, PKE6749748 | BB10: Vaibhav Mishra, Shashi Pratap Singh, Sachin Chauhan, Satendra Kumar, Amit Pandey, Ram Shankar, Nitin Srivastava, Rahul Harishankar, Harish Johar, Devendra AsthaVivek Gupta, Pawan Kumar | BC10: Sameer Dhar, Sanjeev Kumar, Abhinav Lal, Subhodip Mukherjee, Vineet Kumar | BD10: Agpo Management Services Pvt Ltd - Agra | BE10: Agpo Management Services Pvt Ltd - Agra - Uttar Pradesh | BF10: Agpo Management Services Pvt Ltd - Agra_Collection Agency_Uttar Pradesh | BG10: Agpo Management Services Pvt Ltd - Agra_Repo Agency_Uttar Pradesh
A11: 7 | B11: Z20543 | C11: 25557 | D11: East | E11: Bihar | F11: Patna | G11: Collection & Repossession Agency | H11: Aim Corporate - Patna | I11: Sanjay Gupta | J11: Sanjay Gupta/Suresh Bisoi | K11: A/56,Housing Colony Lohiyanagar,Kankarbagh Patna Bihar_800020 | L11: 86480,30702,9007374460,9874289876,7595900524 | M11: 86480,30702,9007374460,9836763581,7044067822,9051761080,8697789378,8296720891,6290612984,8910991842,9804445016,9038223935,9874930018,9874289876,7980165338,9832055052,7001938434,7000482645,9098301963,8240590554,9002842557,8319378592,7718236167,8777381034,9977401420,9826122732,9062106927,7595900524,9830343106 | N11: 8697564337 | O11: collections5@aimcorporate.co | P11: NA | Q11: AVBPG1374M | S11: 19AVBPG1374M2ZD | V11: YES BANK LIMITED | X11: Properitoryship | Y11: Active | Z11: 43283 | AA11: 43281 | AD11: Repo activity added in Dec 21,Email id change req recd on 14th Jun. Supplementary agreement added for Jamshedpur Bhubaneshwar on 3rd Aug'22 | AE11: 25557 | AF11: Aim Corporate | AG11: 1287 | AH11: 1305 | AI11: 1328 | AJ11: 3920 | AK11: 16 | AL11: Allocaton given by Collection & Repossession | AM11: Eligible for audit | AN11: KGAC | AO11: Biswarup Ghosh | AP11: A/56,Housing Colony Lohiyanagar,Kankarbagh Patna Bihar_800020 | AQ11: Audited | AR11: Audited for Collection Only, as no activity of repossession are done for the audit quarter | AT11: Manoj | AU11: Vikky Kumar | AV11: 9354241930 | AW11: 46134 | AX11: Kumar Gaurav Agarwal & company | AY11: Patna | AZ11: Bihar | BA11: KSE6767729, SME6784348, IEE6769906, PME6771779, RBE6757282, DSE6782069, SNE6610031, ASE6777499, TSE6288042, NKE6754736, RHE6158002, ABE6771337, OAE6762281, SGE6696032, MAE6785142, JME6788432 | BB11: Krishnendu Sarder, Saisab Mallick, Imran Elahi, Priyanka Mondal, Ritam Basak, Deepak Singh, Suryanarayan Nayak, Arindam Sarkar, Tarkeshwar Singh, Nishant Kumar, Rajkumar Hazra, Abhisek Bose, Ossam Aditya, Soumitra Ghosh, Monawwar Alam, Jayadev Mishra | BC11: Subhasis Banerjee, Biswarup Ghosh, Md Shabbir Alam | BD11: Aim Corporate - Patna | BE11: Aim Corporate - Patna - Bihar | BF11: Aim Corporate - Patna_Collection Agency_Bihar
A12: 10 | B12: Yblv1132 | C12: 307991 | D12: North | E12: Delhi | F12: Delhi | G12: Collection & Repossession Agency | H12: Ambitious Enterprises | I12: Rameshwar Jaiswal | J12: Rameshwar Jaiswal | K12: Rz-154A , Main Najafgarh Road, Uttam Nagar Delhi | L12: 7303036357 | M12: 7303036357 | N12: 7303036357 | O12: ambitiousenterprises5@gmail.com,ambitiousenterprises2@gmail.com | P12: NA | Q12: CHNPJ3651C | S12: 07CHNPJ3651C1ZG | V12: AU SMALL FINANCE BANK | X12: Properitoryship | Y12: Active | Z12: 45680 | AA12: 45679 | AE12: 307991 | AF12: AMBITIOUS ENTERPRISES | AG12: 140 | AH12: 78 | AI12: 121 | AJ12: 339 | AL12: Allocaton given by Collection agency | AM12: Eligible for audit | AN12: KGAC | AO12: Sameer Dhar | AP12: Rz-154A , Main Najafgarh Road, Uttam Nagar Delhi | AQ12: Audited | AR12: NA | AT12: Akhilesh Kumar Tripahi | AU12: Rahul Verma | AV12: 9354183359 | AW12: 46126 | AX12: Kumar Gaurav Agarwal & company | AY12: Delhi | AZ12: Delhi | BA12: NSE6771909, SKE5835012, MSE6236002, SRE6739824, NRE6746973 | BB12: Narinder Singh, Sushim Kumar, Manpreet Singh(Auto), Syed Razavdeep Rastogi | BC12: Sanjeev Kumar, Sameer Dhar | BD12: Ambitious Enterprises | BE12: Ambitious Enterprises - Delhi | BF12: Ambitious Enterprises_Collection Agency_Delhi
A13: 101 | B13: Z20543 | C13: 25557 | D13: East | E13: West Bengal | F13: Kolkata | G13: Collection & Repossession Agency | H13: Aim Corporate - Kolkata | I13: Sanjay Gupta | J13: Sanjay Gupta/Suresh Bisoi | K13: 17/3 Sahapur Colony New Alipore, Kolkata-700053 | L13: 86480,30702,9007374460,9874289876,7595900524 | M13: 86480,30702,9007374460,9836763581,7044067822,9051761080,8697789378,8296720891,6290612984,8910991842,9804445016,9038223935,9874930018,9874289876,7980165338,9832055052,7001938434,7000482645,9098301963,8240590554,9002842557,8319378592,7718236167,8777381034,9977401420,9826122732,9062106927,7595900524,9830343106 | N13: 8697564337 | O13: collections5@aimcorporate.co | P13: NA | Q13: AVBPG1374M | S13: 19AVBPG1374M2ZD | V13: YES BANK LIMITED | X13: Properitoryship | Y13: Active | Z13: 43283 | AA13: 43281 | AD13: Repo activity added in Dec 21,Email id change req recd on 14th Jun. Supplementary agreement added for Jamshedpur Bhubaneshwar on 3rd Aug'22 | AE13: 25557 | AF13: Aim Corporate | AG13: 1287 | AH13: 1305 | AI13: 1328 | AJ13: 3920 | AK13: 16 | AL13: Allocaton given by Collection & Repossession | AM13: Eligible for audit | AN13: KGAC | AO13: Biswarup Ghosh | AP13: 17/3 Sahapur Colony New Alipore, Kolkata-700053 Office Adders-34/ | AQ13: Audited | AR13: NA | AT13: Payal | AU13: Vikky Kumar | AV13: 9354241930 | AW13: 46121 | AX13: Kumar Gaurav Agarwal & company | AY13: Kolkata | AZ13: West Bengal | BA13: KSE6767729, SME6784348, IEE6769906, PME6771779, RBE6757282, DSE6782069, SNE6610031, ASE6777499, TSE6288042, NKE6754736, RHE6158002, ABE6771337, OAE6762281, SGE6696032, MAE6785142, JME6788432 | BB13: Krishnendu Sarder, Saisab Mallick, Imran Elahi, Priyanka Mondal, Ritam Basak, Deepak Singh, Suryanarayan Nayak, Arindam Sarkar, Tarkeshwar Singh, Nishant Kumar, Rajkumar Hazra, Abhisek Bose, Ossam Aditya, Soumitra Ghosh, Monawwar Alam, Jayadev Mishra | BC13: Subhasis Banerjee, Biswarup Ghosh, Md Shabbir Alam | BD13: Aim Corporate - Kolkata | BE13: Aim Corporate - Kolkata - West Bengal | BF13: Aim Corporate - Kolkata_Collection Agency_West Bengal | BG13: Aim Corporate - Kolkata_Repo Agency_West Bengal
A14: 181 | B14: NA | C14: 312995 | D14: North | E14: Uttar Pradesh | F14: Varanasi | G14: Repossession Agency | H14: Akhand Motors | I14: Akhand Ppratap Singh | J14: Akhand Ppratap Singh | K14: Vill Dalipur , Post - Mangari, Near Babatpur Airport Varanasi 221202 | L14: 8004555581 | M14: 8004555581 | N14: 8004555581 | O14: akhandmotors80@gmail.com | P14: NA | Q14: LYXPS0898G | S14: 09LYXPS0898G1Z2 | V14: HDFC BANK LTD | X14: Properitoryship | Y14: Active | Z14: 45670 | AA14: 45667 | AD14: New Repossession project | AE14: 312995 | AF14: AKHAND MOTORS | AG14: NA | AH14: NA | AI14: NA | AJ14: NA | AK14: 3 | AL14: Allocaton given by Repo agency | AM14: Eligible for audit | AN14: KGAC | AO14: #N/A | AP14: Vill Dalipur , Post - Mangari, Near Babatpur Airport Varanasi 221202 | AQ14: Audited | AR14: NA | AT14: Aditya Pratap Singh | AU14: Chandan Sharma | AV14: 7753851136 | AW14: 46120 | AX14: Kumar Gaurav Agarwal & company | AY14: Varanasi | AZ14: Uttar Pradesh | BA14: NA | BB14: Vivek Kumar Shukla, Sourabh Parihar, Punit Chhotelal Sharma | BC14: Dipak Mangaldas Dhandhukiya, Sanjeev Kumar | BD14: Akhand Motors | BE14: Akhand Motors - Varanasi - Uttar Pradesh | BF14: Akhand Motors_Collection Agency_Varanasi_Uttar Pradesh | BG14: Akhand Motors_Repo Agency_Varanasi_Uttar Pradesh
A15: 53 | B15: NA | C15: 313005 | D15: North | E15: Punjab | F15: Patiala | G15: Collection & Repossession Agency | H15: Ar Associates | I15: Anmol Kumar | J15: Anmol Kumar | K15: Sco 131 Chhoti Baradari, Patiala, Patiala | L15: 7355443003 | M15: 7355443003 | N15: 7355443003 | O15: ARassociate0786@gmail.com | P15: NA | Q15: GCIPK9297P | S15: 03GCIPK9297P1ZL | V15: STATE BANK OF INDIA | X15: Properitoryship | Y15: Active | Z15: 45685 | AA15: 45685 | AE15: 313005 | AF15: AR ASSOCIATES | AG15: 100 | AH15: 107 | AI15: 93 | AJ15: 300 | AL15: Allocaton given by Collection agency | AM15: Eligible for audit | AN15: KGAC | AO15: Ashutosh Gupta | AP15: Sethi Complex 2Nd Floor, Above Icici Bank Near Polo Ground, Patiala | AQ15: Audited | AR15: NA | AT15: Anmol Kumar | AU15: Aman Monga | AV15: 9990034588 | AW15: 46135 | AX15: Kumar Gaurav Agarwal & company | AY15: Patiala | AZ15: Punjab | BA15: MKE6407056 | BB15: Maninder Kumar | BC15: Ashutosh Gupta | BD15: Ar Associates | BE15: Ar Associates - Patiala - Punjab | BF15: Ar Associates_Collection Agency_Patiala_Punjab
A16: 24 | B16: NA | C16: 309009 | D16: North | E16: Uttar Pradesh | F16: Agra | G16: Collection & Repossession Agency | H16: Ansh Enterprises | I16: Rakesh Kumar | J16: Rakesh Kumar | K16: Shop No 5 , 1 St Floor Block 25 , Clothe Market Sanjay Palace Agra 283102 | L16: 9634815557 | M16: 9634815557 | N16: 9634815557 | O16: info@anshenterprise.co.in | P16: NA | Q16: CJSPD0387A | S16: 09CJSPD0387A2Z8 | V16: YES BANK LIMITED | X16: Properitoryship | Y16: Active | Z16: 45680 | AA16: 45679 | AD16: New Repossession project | AE16: 309009 | AF16: ANSH ENTERPRISES | AG16: 111 | AH16: 152 | AI16: 133 | AJ16: 396 | AK16: 2 | AL16: Allocaton given by Collection & Repossession | AM16: Eligible for audit | AN16: KGAC | AO16: NA | AP16: Shop No 5 , 1 St Floor Block 25 , Clothe Market Sanjay Palace Agra 283102 | AQ16: Audited | AR16: NA | AT16: Rakesh Chahat | AU16: Chandan Sharma | AV16: 7753851136 | AW16: 46128 | AX16: Kumar Gaurav Agarwal & company | AY16: Agra | AZ16: Uttar Pradesh | BA16: RSE6763776, GKE6543092 | BB16: Ram Shankar, Govind Kumar | BC16: Rohit Nijhawan | BD16: Ansh Enterprises | BE16: Ansh Enterprises - Agra - Uttar Pradesh | BF16: Ansh Enterprises_Collection Agency_Agra_Uttar Pradesh | BG16: Ansh Enterprises_Repo Agency_Agra_Uttar Pradesh
A17: 67 | B17: NA | C17: 365999 | D17: North | E17: Rajasthan | F17: Jaipur | G17: Collection & Repossession Agency | H17: Bank Bridge Solution | I17: Meena Devi | J17: Meena Devi | K17: Floor No. Part - B, Basement Floor, Plot No - 1179, Sakal Sumangal, Rani Sati Nagar, Nirman Nagar, Jaipur - 302019 | L17: 9828067001 | M17: 9828067001 | N17: 9828067001 | O17: Bankbridgesolution@gmail.com | P17: NA | Q17: FWFPD6079G | S17: 08FWFPD6079G1ZA | X17: Properitoryship | Y17: Active | Z17: 45965 | AA17: 45965 | AD17: Supplementary done on 4th Nov 25 | AE17: 365999 | AF17: BANK BRIDGE SOLUTION | AG17: 330 | AH17: 369 | AI17: 612 | AJ17: 1311 | AL17: Allocaton given by Collection agency | AM17: Eligible for audit | AN17: KGAC | AO17: NA | AP17: Floor No. Part - B, Basement Floor, Plot No - 1179, Sakal Sumangal, Rani Sati Nagar, Nirman Nagar, Jaipur - 302019 | AQ17: Audited | AR17: NA | AT17: Anil Swami / 7976225567 | AU17: Akash Sharma | AV17: 7688959606 | AW17: 46128 | AX17: Kumar Gaurav Agarwal & company | AY17: Jaipur | AZ17: Rajasthan | BA17: PSE6778569 | BB17: Pravesh Sharma | BC17: Na | BD17: Bank Bridge Solution | BE17: Bank Bridge Solution - Jaipur - Rajasthan | BF17: Bank Bridge Solution_Collection Agency_Jaipur_Rajasthan
A18: 8 | B18: NA | C18: 313004 | D18: East | E18: Chhattisgarh | F18: Raipur | G18: Collection & Repossession Agency | H18: Anurag Agency | I18: Anurag Rathi | J18: Anurag Rathi | K18: 3Rd Floor,Hanumanta Complex,Near Mansu Realty Ring Road No. 1 Agoraha Colony Raipura Raipur (492013) | L18: 9893023143 | M18: 9893023143 | N18: 9893023143 | O18: ANURAGRATHI1010@GMAIL.COM ; aa.y@anuragagency.com | P18: NA | Q18: AIJPR0004N | S18: 22AIJPR0004N2ZE | V18: YES BANK LIMITED | X18: Properitoryship | Y18: Active | Z18: 45621 | AA18: 45618 | AE18: 313004 | AF18: Anurag Agency | AG18: 635 | AH18: 615 | AI18: 608 | AJ18: 1858 | AL18: Allocaton given by Collection agency | AM18: Eligible for audit | AN18: KGAC | AO18: - | AP18: 3Rd Floor,Hanumanta Complex,Near Mansu Realty Ring Road No. 1 Agoraha Colony Raipura Raipur (492013) | AQ18: Audited | AR18: Audited for collection and Repossessoin, as agency have repo of assest in the audit quarter | AT18: Namarta Sharma / 8770534356 | AU18: Parteek Yadav | AV18: 7460008081 | AW18: 46125 | AX18: Kumar Gaurav Agarwal & company | AY18: Raipur | AZ18: Chhattisgarh | BA18: VUE6755300, RQE6781542, ASE6778431, SME6345002, MKE6775854, ADE6782782 | BB18: Vikram Upadhyay, Rizwan Quraishi, Avtar Singh, Sudarshan Maddu, Manoj Kumar, Anindh Dubey | BC18: Saurabh Chaturvedi, Biswarup Ghosh, Md Shabbir Alam, -, Saurabh Chaturvedi , Bikram Chakraborty | BD18: Anurag Agency | BE18: Anurag Agency - Raipur - Chhattisgarh | BF18: Anurag Agency_Collection Agency_Raipur_Chhattisgarh | BG18: Anurag Agency_Repo Agency_Raipur_Chhattisgarh
A19: 157 | B19: Z16312 | C19: 54034 | D19: North | E19: Rajasthan | F19: Jaipur | G19: Collection/Pickup/Repo Agency | H19: Choudhary Brothers Group - Jaipur | I19: Ashok Choudhary | J19: Ashok Choudhary | K19: Head Office Address : C 70 Kashyap Path, Janpath, Shyam Nagar Jaipur 302006 | L19: 9829295353,01414919039 | M19: 9829295353,01414919039,9610449872,9887603519,6375273571,8696397777,9529123413,9001811855,9024720814,9829221122 | N19: 9929295353 | O19: cbgroupjaipur01@gmail.com | P19: cbgalwar2018@gmail.com; cbgroup.alwar@gmail.com | Q19: AAIFC4465F | R19: ANPPC7352RSD001 | S19: 08AAIFC4465F1ZF | V19: HDFC BANK LTD | X19: Partnership | Y19: Active | Z19: 42877 | AA19: 42876 | AE19: 54034 | AF19: Choudhary Brothers Group | AG19: 781 | AH19: 692 | AI19: 685 | AJ19: 2158 | AL19: Allocaton given by Collection agency | AM19: Eligible for audit | AN19: KGAC | AO19: Ashutosh Gupta | AP19: Head Office Address : C 70 Kashyap Path, Janpath, Shyam Nagar Jaipur 302006 | AQ19: Audited | AR19: NA | AT19: Pushpendra Choudhary / 9829221122 | AU19: Akash Sharma | AV19: 7688959606 | AW19: 46132 | AX19: Kumar Gaurav Agarwal & company | AY19: Jaipur | AZ19: Rajasthan | BA19: SCE6758746, SKE6777255, RSE6771124, PSE6777607, T23418, SME5900019, KDE6778345, RSE6782005 | BB19: Sunil Choudhary, Sandeep Kumar, Ranjan Solanki, Pramod Sankhala, Nilesh Pednekar, Siddharth Maharishi, Kailash Devanda, Rajveer Singh | BC19: Ashutosh Gupta, Sanjeev Kumar, Sameer Dhar, Pawan Rana | BD19: Choudhary Brothers Group - Jaipur | BE19: Choudhary Brothers Group - Jaipur - Rajasthan | BF19: Choudhary Brothers Group - Jaipur_Collection Agency_Rajasthan
A20: 19 | B20: Z24482 | C20: 45704 | D20: North | E20: Delhi | F20: Delhi | G20: Collection & Repossession Agency | H20: Shree Balaji | I20: Jitender Dhaiya | J20: Jitender Dhaiya | K20: C - 2/395, 3Rd Floor Back Side, Janakpuri, Delhi 110058 | L20: 9999999276 | M20: 9899177177 | N20: 9999999276 | O20: info@shreebalaji276.in | P20: shreebalaji276@gmail.com | Q20: AKWPD7176N | S20: 07AKWPD7176N1Z9 | V20: YES BANK LIMITED | X20: Properitoryship | Y20: Active | Z20: 44183 | AA20: 44183 | AD20: Add change req recd in May22 | AE20: 45704 | AF20: Shree Balaji | AG20: 531 | AH20: 624 | AI20: 352 | AJ20: 1507 | AK20: 7 | AL20: Allocaton given by Collection & Repossession | AM20: Eligible for audit | AN20: KGAC | AO20: Amit Sharma | AP20: NA | AQ20: Not Audited | AR20: Audit Failed due to non cooperation. | AS20: NA | AT20: NA | AU20: NA | AV20: NA | AW20: NA | AX20: NA | AY20: Delhi | AZ20: Delhi | BA20: ASE6770928, SKE6779366, RSE6776115, SKE5835012, MKE5878004, SSE6776468, VGE6773224, RAE6783127, SPE6776273, NKE6775741, KKE6777919 | BB20: Aanchal Singh, Sumit Kumar, Rahul Sharma, Sushim Kumar, Manish Kumar, Subhash Sharma, Vishal Gupta, Rittin Arya, Sushant Parashar, Nitin Kumar, Kamal Kumar | BC20: Sanjeev Kumar, Amit Sharma | BD20: Shree Balaji | BE20: NA | BF20: NA | BG20: NA
A21: 48 | B21: NA | C21: 190972 | D21: North | E21: Punjab | F21: Chandigarh | G21: Collection & Repossession Agency | H21: Citi Enterprises | I21: Dinesh Midha | J21: Dinesh Midha | K21: Sco-87, 1St Floor, , Sector-40C, , Chandigarh -160036 | L21: 9815009116 | M21: 9815009116 | N21: 9815009116 | O21: Dinesh.midha@citibesteam.com | P21: NA | Q21: ACBPM4580E | S21: 04ACBPM4580E1ZX | V21: YES BANK LIMITED | X21: Properitoryship | Y21: Active | Z21: 45538 | AA21: 45537 | AD21: Supplementary agreement done in Sept'24,Supplementary agreement done in March'25 | AE21: 190972 | AF21: CITI ENTERPRISES | AG21: 1339 | AH21: 1073 | AI21: 1206 | AJ21: 3618 | AL21: Allocaton given by Collection agency | AM21: Eligible for audit | AN21: KGAC | AO21: NA | AP21: Sco-87, 1St Floor, , Sector-40C, , Chandigarh -160036 | AQ21: Audited | AR21: NA | AT21: Radhika | AU21: Rahul Verma | AV21: 9354183359 | AW21: 46132 | AX21: Kumar Gaurav Agarwal & company | AY21: Chandigarh | AZ21: Punjab | BA21: SSE6775469, VKE6782576, SRE6782838, SSE6748795 | BB21: Sukhwinder Singh, Vikash Kumar, Sidharth RaSukhwant Singh | BC21: Na | BD21: Citi Enterprises | BE21: Citi Enterprises - Chandigarh - Punjab | BF21: Citi Enterprises_Collection Agency_Chandigarh_Punjab
A22: 147 | B22: NA | C22: 165960 | D22: East | E22: West Bengal | F22: Kolkata | G22: Collection Agency | H22: Credit Solution | I22: Prasanta Saha | J22: Prasanta Saha | K22: 20/1, Plot, 100 Sahapur Colony, New Alipore, Kolkata- 700053 | L22: 9836363123 , 7449756305 | M22: 9836363123 , 7449756305 | N22: 9836363123 , 7449756305 | O22: CREDITSOLUTIONKOLKATA@GMAIL.COM ; debtreco@cesolution.co.in | P22: NA | Q22: AXAPS5363D | S22: 19AXAPS5363D2ZC | X22: Properitoryship | Y22: Active | Z22: 45559 | AA22: 45559 | AD22: Supplementary agreement done in Sept'24 // Addition of Bkt 3&4 for PL,BL | AE22: 165960 | AF22: Credit Solution | AG22: 235 | AH22: 256 | AI22: 395 | AJ22: 886 | AL22: Allocaton given by Collection agency | AM22: Eligible for audit | AN22: KGAC | AO22: Ashutosh Gupta | AP22: 20/1, Plot, 100 Sahapur Colony, New Alipore, Kolkata- 700053 | AQ22: Audited | AR22: NA | AT22: Manish Kunar Barick | AU22: Vikky Kumar | AV22: 9354241930 | AW22: 46121 | AX22: Kumar Gaurav Agarwal & company | AY22: Kolkata | AZ22: West Bengal | BA22: KSE6767729, SDE6781658 | BB22: Krishnendu Sarder, Sujoy Das | BC22: Ashutosh Gupta | BD22: Credit Solution | BE22: Credit Solution - Kolkata - West Bengal | BF22: Credit Solution_Collection Agency_Kolkata_West Bengal
A23: 64 | B23: Z27683 | C23: 51542 | D23: North | E23: Rajasthan | F23: Bikaner | G23: Collection & Repossession Agency | H23: D S Associates | I23: Dhnshree Swami | J23: Om Prakash Swami | K23: Shop No. 7, Near Vishvkarma Gate, Near Shree Ram Mandir, Bikaner - 334001 | L23: 9983965443 | M23: 9983965443 | N23: 9214419806 | O23: dsassociates2016@gmail.com | P23: NA | Q23: GPMPS2855J | R23: NA | S23: 08GPMPS2855J1Z2 | X23: Properitoryship | Y23: Active | Z23: 44890 | AA23: 44890 | AE23: 51542 | AF23: D S Associates | AG23: 289 | AH23: 286 | AI23: 297 | AJ23: 872 | AL23: Allocaton given by Collection agency | AM23: Eligible for audit | AN23: KGAC | AO23: - | AP23: Shop No. 7, Near Vishvkarma Gate, Near Shree Ram Mandir, Bikaner - 334001 | AQ23: Audited | AR23: NA | AT23: Mukul Ramawat / 8209758199 | AU23: Akash Sharma | AV23: 7688959606 | AW23: 46119 | AX23: Kumar Gaurav Agarwal & company | AY23: Bikaner | AZ23: Rajasthan | BA23: MCE6212008, SSE6776468, DKE6771022, ATE6773431, LCE6760405, PKE6777451 | BB23: Mahendra Chouhan, Subhash Sharma, Dinesh Kumar, Ashish Tiwari, Lal Chand Chimpa, Pawan Kumar | BC23: Ashutosh Gupta, Kalpesh Raval, Sameer Dhar, Sanjeev Kumar, Pawan RaVivek Joshi, - | BD23: D S Associates | BE23: D S Associates - Bikaner - Rajasthan | BF23: D S Associates_Collection Agency_Bikaner_Rajasthan
A24: 34 | B24: NA | C24: 310986 | D24: East | E24: Jharkhand | F24: Ranchi | G24: Collection & Repossession Agency | H24: Definate Solutions | I24: Nisha | J24: Nisha | K24: Dubey Colony,Tetri Toli,Nakmkum, Ranchi,834010,Jharkhand, Dubey Colony,Tetri Toli,Nakmkum, Ranchi,834010,Jharkhand, Dubey Colony,Tetri Toli,Nakmkum, Ranchi,834010,Jhar | L24: 8083983999 | M24: 8083983999 | N24: 8083983999 | O24: definatesolutions.rnc@gmail.com ; dsy.rnc@gmail.com | P24: NA | Q24: AUSPD7846D | S24: 20AUSPD7846D1ZP | V24: PUNJAB NATIONAL BANK | X24: Properitoryship | Y24: Active | Z24: 45668 | AA24: 45665 | AD24: New Repossession project | AE24: 310986 | AF24: DEFINATE SOLUTIONS | AG24: 99 | AH24: 99 | AI24: 102 | AJ24: 300 | AL24: Allocaton given by Collection agency | AM24: Eligible for audit | AN24: KGAC | AO24: Subhasis Banerjee | AP24: Dubey Colony,Tetri Toli,Nakmkum, Ranchi,834010,Jharkhand, Dubey Colony,Tetri Toli,Nakmkum, Ranchi,834010,Jharkhand, Dubey Colony,Tetri Toli,Nakmkum, Ranchi,834010,Jhar | AQ24: Audited | AR24: NA | AT24: Nisha | AU24: Vikky Kumar | AV24: 9354241930 | AW24: 46130 | AX24: Kumar Gaurav Agarwal & company | AY24: Ranchi | AZ24: Jharkhand | BA24: RME6754808 | BB24: Rabi Mishra | BC24: Subhasis Banerjee | BD24: Definate Solutions | BE24: Definate Solutions - Ranchi - Jharkhand | BF24: Definate Solutions_Collection Agency_Ranchi_Jharkhand
A25: 82 | B25: NA | C25: 347001 | D25: North | E25: Uttar Pradesh | F25: Ayodhya | G25: Collection & Repossession Agency | H25: Awadhesh Kumar Dubey | I25: Awadhesh Kumar Dubey | J25: Awadhesh Kumar Dubey | K25: Chandpur Harvansh Purbi, Chandpur Harbanshpur Po Dabha Semar Disct.Ayodhya Up 224133 | L25: 9450916368 | M25: 9450916368 | N25: 9450916368 | O25: dubey_awadhesh@rediffmail.com | P25: NA | Q25: AHAPD1739N | S25: 09AHAPD1739N1Z9 | X25: Proprietorship | Y25: Active | Z25: 45840 | AA25: 45838 | AE25: 347001 | AF25: AWADHESH KUMAR DUBEY | AG25: NA | AH25: NA | AI25: NA | AJ25: NA | AK25: 1 | AL25: Allocaton given by Repo agency | AM25: Eligible for audit | AN25: KGAC | AO25: #N/A | AP25: Chandpur Harvansh Purbi, Chandpur Harbanshpur Po Dabha Semar Disct.Ayodhya Up 224133 | AQ25: Audited | AR25: NA | AT25: Vijay Dube | AU25: Chandan Sharma | AV25: 7753851136 | AW25: 46119 | AX25: Kumar Gaurav Agarwal & company | AY25: Ayodhya | AZ25: Uttar Pradesh | BA25: NA | BB25: Shyam Parkash, Vivek Kumar Shukla | BC25: Abhinav Lal | BD25: Awadhesh Kumar Dubey | BE25: Awadhesh Kumar Dubey - Ayodhya - Uttar Pradesh | BF25: Awadhesh Kumar Dubey_Collection Agency_Ayodhya_Uttar Pradesh | BG25: Awadhesh Kumar Dubey_Repo Agency_Ayodhya_Uttar Pradesh
A26: 12 | B26: Z25246 | C26: 26364 | D26: North | E26: Delhi | F26: Delhi | G26: Collection & Repossession Agency | H26: Earth Services | I26: Subhash Chand | J26: Subhash Chand | K26: Wz-12 Kh No2882/738 1St , Floor Kailash Park, Nd-15 | L26: 01149148479 | M26: 01149148479,7303542742,9210171819,9911632358,9717706206,9871666049,9560827618,9953547789 | N26: 9711567008 | O26: earth4@earthservices.in | P26: earthservices17@gmail.com | Q26: AEGPC6483B | R26: 07AEGPC6483BSD001 | S26: 07AEGPC6483B2ZR | V26: YES BANK LIMITED | X26: Proprietorship | Y26: Active | Z26: 44391 | AA26: 44392 | AD26: Repo activity added in May22 | AE26: 26364 | AF26: Earth Services | AG26: 2128 | AH26: 2131 | AI26: 1953 | AJ26: 6212 | AL26: Allocaton given by Collection agency | AM26: Eligible for audit | AN26: KGAC | AO26: Ashutosh Gupta | AP26: Wz-12 Kh No2882/738 1St , Floor Kailash Park, Nd-15 | AQ26: Audited | AR26: NA | AT26: Mithlesh Kumar | AU26: Pawan Kumar | AV26: 9582917652 | AW26: 46134 | AX26: Kumar Gaurav Agarwal & company | AY26: Delhi | AZ26: Delhi | BA26: NKE6775741, AKE6778416, SRE6782838, RSE6776475, VKE6782576, SSE6775469, MME6755196, VGE6773224, SSE6748795 | BB26: Nitin Kumar, Amit Kumar, Sidharth RaRupesh Singh, Vikash Kumar, Sukhwinder Singh, Mritunjay MunVishal Gupta, Sukhwant Singh | BC26: Ashutosh Gupta | BD26: Earth Services | BE26: Earth Services - Delhi | BF26: Earth Services_Collection Agency_Delhi
A27: 26 | B27: NA | C27: 315002 | D27: North | E27: Haryana | F27: Hisar | G27: Collection & Repossession Agency | H27: Port Care Consultancy | I27: Neeraj Kumar | J27: Neeraj Kumar | K27: Sco No.-153, , 3Rd Floor, Red Square Market,Hisar,Haryana-125001 | L27: 9355511114 | M27: 9355511114 | N27: 9355511114 | O27: khyalia.vinod@gmail.com | P27: NA | Q27: AWNPK8831A | S27: 06AWNPK8831A2ZJ | V27: YES BANK LIMITED | X27: Properitoryship | Y27: Active | Z27: 45698 | AA27: 45695 | AE27: 315002 | AF27: PORT CARE CONSULTANCY | AG27: 3 | AH27: 0 | AI27: 0 | AJ27: 3 | AL27: Allocaton given by Collection agency | AM27: Eligible for audit | AN27: KGAC | AO27: Sanjeev Kumar | AP27: NA | AQ27: Not Audited | AR27: Low allocation in January and no allocation afterwards | AS27: NA | AT27: NA | AU27: NA | AV27: NA | AW27: NA | AX27: NA | AY27: Hisar | AZ27: Haryana | BA27: ANE5784049 | BB27: Anil Kumar Nandal | BC27: Sanjeev Kumar | BD27: Port Care Consultancy | BE27: NA | BF27: NA | BG27: NA
A28: 40 | B28: NA | C28: 347002 | D28: East | E28: Odisha | F28: Cuttack | G28: Collection & Repossession Agency | H28: B K Associates | I28: Basanta Kumar Swain,Sasmita Swain,Bibhu Sundar Jena | J28: Basanta Kumar Swain,Sasmita Swain,Bibhu Sundar Jena | K28: At Rajesndranagar,Temple Side Lane Near Mangala Mandir,Madhupatna,Cuttack,Odisha,753010 | L28: 9937173611 | M28: 9937173611 | N28: 9937173611 | O28: bkassociates3611@gmail.com, bkcollection2018@gmail.com | P28: NA | Q28: AAMFB1648R | S28: 21AAMFB1648R2Z3 | X28: Patnership | Y28: Active | Z28: 45840 | AA28: 45836 | AE28: 347002 | AF28: B K Associates | AG28: NA | AH28: NA | AI28: NA | AJ28: NA | AK28: 2 | AL28: Allocaton given by Repo agency | AM28: Eligible for audit | AN28: KGAC | AO28: #N/A | AP28: At Rajesndranagar,Temple Side Lane Near Mangala Mandir,Madhupatna,Cuttack,Odisha,753010 | AQ28: Audited | AR28: NA | AT28: Bibhusundar Jena | AU28: Vikky Kumar | AV28: 9354241930 | AW28: 46125 | AX28: Kumar Gaurav Agarwal & company | AY28: Cuttack | AZ28: Odisha | BA28: NA | BB28: Santosh Sharma, Suryanarayan Nayak | BC28: Biswarup Ghosh | BD28: B K Associates | BE28: B K Associates - Cuttack - Odisha | BF28: B K Associates_Collection Agency_Cuttack_Odisha | BG28: B K Associates_Repo Agency_Cuttack_Odisha
A29: 28 | B29: Z22853 | C29: 26490 | D29: North | E29: Haryana | F29: Panipat | G29: Collection & Repossession Agency | H29: G.D.M. Management Services Pvt Ltd - Panipat | I29: Rajesh Kumar/Naresh Kumar | J29: Rajesh Kumar/Naresh Kumar | K29: Prince Guest House, Room No.2-B,Near Axis Bank, G T Road, Panipat-132103 | L29: 011,40919715,9354909242,9315045873,7678326675,7827410614,8882896148,8595955476,8882818651,9315131930,8178036157,8851243856,7827429289,76783918128076508276,8882899467,8595956472,7678321553,7678308077,7678396018,8920038807,8368999916,8810592365,9315748638,7678324044,8882403961,8595954459,8076608859,8076534454,8920963073,8920038738 | M29: 011,40919715,9354909242,9315045873,7678326675,7827410614,8882896148,8595955476,8882818651,9315131930,8178036157,8851243856,7827429289,76783918128076508276,8882899467,8595956472,7678321553,7678308077,7678396018,8920038807,8368999916,8810592365,9315748638,7678324044,8882403961,8595954459,8076608859,8076534454,8920963073,8920038738,7292030107,9999098611,9891999980,7017538011,9810205430,9958686165,9266697828,9817875090,9671775656,9992202126,9050604254,9667169442,8851473697,7065315053,7065954659,7065963209,7065640923,8750131886,8750773816,8750273692,8750967594,8750172809,8750973013,8750537906,8750957629,8750900871,8588893713,8588842445,8588847253,8750177170,8750094542,7065502925,7065494502,7065936794,7065784203,7065675119,7065680813,7065334058,7065610331,8588845250,8588875903,8588891770,8588858236,8588876523,8588846304,7669627101,7669794829,7669591561,7669898316,7669794921,7669201607,7669818304,7669836846,7669803373,7669201593,7669614273,7669764163,7669794879,7669646432,7669516059,7669595815,7669616520,7669988972,7669886976,7669614267,7669573471,7669196176,7669827710,7669675347,7669614262,8929665273,8929110705,8929988714,8929447921,8929727441,8929925517,8929843241 | N29: 9896400088,9354909242 | O29: goodwill_naresh@outlook.com ; gdmdebtmanagement@outlook.com | P29: NA | Q29: AAHCG6535C | S29: 06AAHCG6535C1ZT | V29: ICICI BANK LIMITED | X29: PVT Ltd | Y29: Active | Z29: 43724 | AA29: 43704 | AD29: Addition address req received in Sept, Supplementary agreement done on 18th Sep'23 | AE29: 26490 | AF29: G.D.M. Management Services PVT LTD | AG29: 2186 | AH29: 2355 | AI29: 2014 | AJ29: 6555 | AK29: 2 | AL29: Allocaton given by Collection & Repossession | AM29: Eligible for audit | AN29: KGAC | AO29: Ashutosh Gupta | AP29: NA | AQ29: Not Audited | AR29: Visited the agency but audit not done due to agency is working for Yes Bank from their another branch, Address : A-1 1st floor , shastri nagar , new delhi -110034 | AS29: NA | AT29: NA | AU29: NA | AV29: NA | AW29: NA | AX29: NA | AY29: Panipat | AZ29: Haryana | BA29: NRE6746973, SRE6739824, RSE6763776, SRE6782838, RCE6775867, BRE6281007, ANE5784049, ERE6776646, PKE6779360, VME6772902, KSE6769063, MRE6786842 | BB29: Navdeep Rastogi, Syed Raza, Ram Shankar, Sidharth RaRitesh Chourasia, Bhavna Rajput, Anil Kumar Nandal, Ekta Rani, Pawan Kumar, Vaibhav Mishra, Kushpal Singh, Mohit Rathore | BC29: Sameer Dhar, Kunal Malhotra, Sanjeev Kumar, Ashutosh Gupta, Upanshu Bajaj | BD29: G.D.M. Management Services Pvt Ltd - Panipat | BE29: NA | BF29: NA | BG29: NA
A30: 85 | B30: Z26519 | C30: 12290 | D30: North | E30: Uttar Pradesh | F30: Kanpur | G30: Collection & Repossession Agency | H30: Baiswara Associates | I30: Mr Sanjeev Singh | J30: Mr Sanjeev Singh | K30: H-775 Mig World Bank Petrol Line Barra Kanpur -208027 | L30: 9839214520; 7007800000 | M30: 9839214520,9682214520 | O30: baiswaraassociates_2009@rediffmail.com; baiswara@baiswaragroup.com | P30: baiswaraassociates@gmail.com | Q30: AXDPS6196H | R30: 09AXDPS6196H1ZU | S30: 09AXDPS6196H1ZU | V30: CENTRAL BANK OF INDIA | X30: Properitoryship | Y30: Active | Z30: 44609 | AA30: 44603 | AD30: Coolection activity added in Dec22 | AE30: 12290 | AF30: Baiswara Associates | AG30: 41 | AH30: 36 | AI30: 35 | AJ30: 112 | AL30: Allocaton given by Collection agency | AM30: Eligible for audit | AN30: KGAC | AO30: Abhinav Lal | AP30: H-775 Mig World Bank Petrol Line Barra Kanpur -208027 | AQ30: Audited | AR30: Audited for collection and Repossessoin, as agency have repo of assest in the audit quarter | AT30: Himanshu Awashti | AU30: Chandan Sharma | AV30: 7753851136 | AW30: 46123 | AX30: Kumar Gaurav Agarwal & company | AY30: Kanpur | AZ30: Uttar Pradesh | BA30: VGE6786972, NSE6633007 | BB30: Vivek Gupta, Nitin Kumar Singh | BC30: Abhinav Lal | BD30: Baiswara Associates | BE30: Baiswara Associates - Kanpur - Uttar Pradesh | BF30: Baiswara Associates_Collection Agency_Kanpur_Uttar Pradesh | BG30: Baiswara Associates_Repo Agency_Kanpur_Uttar Pradesh
A31: 160 | B31: Z16682 | C31: 25732 | D31: East | E31: West Bengal | F31: Kolkata | G31: Collection/Pickup/Repo Agency | H31: Esolve Solutions Pvt Ltd | I31: Rajesh Gupta | J31: Rajesh Gupta | K31: 1/1 Meredith St, 2Nd Floor, Kolkata - 700072 | L31: 9830006161 | M31: 9830006161,9830553705,7003487878,7003048731, 9674081075 , 6291926035 | N31: 9830006161 | O31: collections.yesbank@e-solvesolutions.com | P31: NA | Q31: AABCE8294Q | S31: 19AABCE8294Q1ZP | V31: YES BANK LIMITED | X31: PVT Ltd | Y31: Active | Z31: 44659 | AA31: 44659 | AD31: Repo activity added | AE31: 25732 | AF31: Esolve solutions PVT LTD | AG31: 1204 | AH31: 1174 | AI31: 1138 | AJ31: 3516 | AL31: Allocaton given by Collection agency | AM31: Eligible for audit | AN31: KGAC | AO31: Ashutosh Gupta | AP31: 1/1 Meredith St, 2Nd Floor, Kolkata - 700072 | AQ31: Audited | AR31: NA | AT31: Somnath Dey | AU31: Pradeep | AV31: 8287823681 | AW31: 46132 | AX31: Kumar Gaurav Agarwal & company | AY31: Kolkata | AZ31: West Bengal | BA31: SDE6778568, MSE6778149, AME6761288, SME6781177, TSE6288042, DSE6782069 | BB31: Suman Das, Md Sarfarazuddin, Md Azharuddin, Sudip ManTarkeshwar Singh, Deepak Singh | BC31: Ashutosh Gupta, Biswarup Ghosh | BD31: Esolve Solutions Pvt Ltd | BE31: Esolve Solutions Pvt Ltd - Kolkata - West Bengal | BF31: Esolve Solutions Pvt Ltd_Collection Agency_Kolkata_West Bengal
A32: 97 | B32: Z28071 | C32: 54117 | D32: North | E32: Uttarakhand | F32: Dehradun | G32: Collection & Repossession Agency | H32: Evergreen Solution | I32: Anand Ballabh Pandey | J32: Anand Ballabh Pandey | K32: B-228 Nehru Colony Dehradun-248001 | L32: 7895100604 | M32: 7895100604 | N32: 9358950033 | O32: evergreen.solution@rediffmail.com; anand.pandey@evergreensolution.org.in | P32: evergreensolutionybl@gmail.com | Q32: BAKPP7912B | S32: 05BAKPP7912B1ZU | V32: YES BANK LIMITED | X32: Properitoryship | Y32: Active | Z32: 44971 | AA32: 44965 | AE32: 54117 | AF32: Evergreen Solution | AG32: 216 | AH32: 207 | AI32: 210 | AJ32: 633 | AL32: Allocaton given by Collection agency | AM32: Eligible for audit | AN32: KGAC | AO32: Abhinav Lal | AP32: B-228 Nehru Colony Dehradun-248001 | AQ32: Audited | AR32: NA | AT32: Aknsha Kumari / 9548597076 | AU32: Akshay Notiyal | AV32: 9149204613 | AW32: 46133 | AX32: Kumar Gaurav Agarwal & company | AY32: Dehradun | AZ32: Uttarakhand | BA32: JSE6775853, HKE6745350, RAE6783127, STE5844128 | BB32: Jeetmani Silswal, Hayat Kathayat, Rittin Arya, Sandeep Tyagi | BC32: Ashutosh Gupta, Sanjeev Kumar, Abhinav Lal, Sameer Dhar | BD32: Evergreen Solution | BE32: Evergreen Solution - Dehradun - Uttarakhand | BF32: Evergreen Solution_Collection Agency_Dehradun_Uttarakhand
A33: 45 | B33: Z15099 | C33: 26517 | D33: North | E33: Punjab | F33: Amritsar | G33: Collection & Repossession Agency | H33: Excel Agencies - Amritsar | I33: Pawandeep Singh | J33: Pawandeep Singh / Pardeep Kumar/Prince Aneja/Sukhdev Chabbra/Tarandeep Singh | K33: Shop No 20, Ssss Complex, Batala Road, Randhwa, Amritsar - 143001 | L33: 0172-4605355,4605245,0181-4608882,0161-4648632 | M33: 0172-4605355,4605245,0181-4608882,0161-4648632,9914141900,6280449688,9872074864,9646689689,7087344321,7986600380,6239609030,9779282827,7888714695,0172-5090526 | N33: 9914141900,9988210298,9317575751 | O33: ;excelbat@yahoo.co.in; excelyes9@gmail.com;exceljal.yesbank@gmail.com;excel.yesbankchd@gmail.com ; excel.yesbank56@gmail.com; excel2019@excelagencies.com | P33: NA | Q33: ANDPS3022N | S33: 03ANDPS3022N1Z2 | V33: YES BANK LIMITED | X33: Properitoryship | Y33: Active | Z33: 43579 | AA33: 43579 | AD33: Address addition details received on 16th Aug,Mohal add change req reced in Oct21. | AE33: 26517 | AF33: Excel Agencies | AG33: 1051 | AH33: 1002 | AI33: 925 | AJ33: 2978 | AL33: Allocaton given by Collection agency | AM33: Eligible for audit | AN33: KGAC | AO33: Ashutosh Gupta | AP33: Shop No 20, Ssss Complex, Batala Road, Randhwa, Amritsar - 143001 | AQ33: Audited | AR33: NA | AT33: Pooja Gupta/8837665745 | AU33: Pawan Kumar | AV33: 9582917652 | AW33: 46125 | AX33: Kumar Gaurav Agarwal & company | AY33: Amritsar | AZ33: Punjab | BA33: PSE6777607, JBE6662016, SGE6771981, SKE6776527, JSE6784665, KDE6778345, SCE6758746 | BB33: Pramod Sankhala, Jaspreet Bhathal, Sahil Gorsi, Sunil Kumar , Jagmohan Singh, Kailash Devanda, Sunil Choudhary | BC33: Ashutosh Gupta | BD33: Excel Agencies - Amritsar | BE33: Excel Agencies - Amritsar - Punjab | BF33: Excel Agencies - Amritsar_Collection Agency_Punjab
A34: 33 | B34: NA | C34: 67899 | D34: East | E34: Jharkhand | F34: Jamshedpur | G34: Collection & Repossession Agency | H34: Sai Enterprises | I34: Bharat Kumar | J34: Bharat Kumar | K34: H No - 06, Vidyapati Nagar, Main Road Baridih, Jamshedpur - 831017 // | L34: 9110166707 | M34: 9110166707 ; 8291720550 | N34: 9110166707 | O34: saienterprisesyb@saient.co.in | P34: NA | Q34: CRXPK1279H | R34: 0 | S34: #N/A | T34: 0 | U34: 0 | V34: YES BANK LIMITED | W34: 0 | X34: Properitoryship | Y34: Active | Z34: 45133 | AA34: 45131 | AB34: 0 | AC34: 0 | AD34: 0 | AE34: 67899 | AF34: Sai Enterprises | AG34: 449 | AH34: 443 | AI34: 439 | AJ34: 1331 | AL34: Allocaton given by Collection agency | AM34: Eligible for audit | AN34: KGAC | AO34: Ashutosh Gupta | AP34: NA | AQ34: Not Audited | AR34: Audited on another address : B/111 subhash road, baagun nagar baridih near AIWC high school po baridih east singhbhum jamshedpur 831017. | AS34: NA | AT34: NA | AU34: NA | AV34: NA | AW34: NA | AX34: NA | AY34: Jamshedpur | AZ34: Jharkhand | BA34: PYE6778749, PKE6762328, STE6769262, CRE6787981 | BB34: Pankaj Yadav, Prabhakar Kumar, Santosh Thakur, Chandan Rishabh | BC34: Ashutosh Gupta, Md Shabbir Alam | BD34: Sai Enterprises | BE34: NA | BF34: NA | BG34: NA
A35: 56 | B35: Z15099 | C35: 26517 | D35: North | E35: Punjab | F35: Ludhiana | G35: Collection & Repossession Agency | H35: Excel Agencies - Ludhiana | I35: Pawandeep Singh | J35: Pawandeep Singh / Pardeep Kumar/Prince Aneja/Sukhdev Chabbra/Tarandeep Singh | K35: Office No. 2, 2Nd Floor, Novelty Plaza, Opp. Park Plaza, Bhai Wala Chowk, Ludhiana - 141001 | L35: 0172-4605355,4605245,0181-4608882,0161-4648632 | M35: 0172-4605355,4605245,0181-4608882,0161-4648632,9914141900,6280449688,9872074864,9646689689,7087344321,7986600380,6239609030,9779282827,7888714695,0172-5090526 | N35: 9914141900,9988210298,9317575751 | O35: ;excelbat@yahoo.co.in; excelyes9@gmail.com;exceljal.yesbank@gmail.com;excel.yesbankchd@gmail.com ; excel.yesbank56@gmail.com; excel2019@excelagencies.com | P35: NA | Q35: ANDPS3022N | S35: 03ANDPS3022N1Z2 | V35: YES BANK LIMITED | X35: Properitoryship | Y35: Active | Z35: 43579 | AA35: 43579 | AD35: Address addition details received on 16th Aug,Mohal add change req reced in Oct21. | AE35: 26517 | AF35: Excel Agencies | AG35: 1051 | AH35: 1002 | AI35: 925 | AJ35: 2978 | AL35: Allocaton given by Collection agency | AM35: Eligible for audit | AN35: KGAC | AO35: Ashutosh Gupta | AP35: Office No. 2, 2Nd Floor, Novelty Plaza, Opp. Park Plaza, Bhai Wala Chowk, Ludhiana - 141001 | AQ35: Audited | AR35: NA | AT35: Sukhdev/9317575751 | AU35: Pawan Kumar | AV35: 9582917652 | AW35: 46127 | AX35: Kumar Gaurav Agarwal & company | AY35: Ludhiana | AZ35: Punjab | BA35: PSE6777607, JBE6662016, SGE6771981, SKE6776527, JSE6784665, KDE6778345, SCE6758746 | BB35: Pramod Sankhala, Jaspreet Bhathal, Sahil Gorsi, Sunil Kumar , Jagmohan Singh, Kailash Devanda, Sunil Choudhary | BC35: Ashutosh Gupta | BD35: Excel Agencies - Ludhiana | BE35: Excel Agencies - Ludhiana - Punjab | BF35: Excel Agencies - Ludhiana_Collection Agency_Punjab
A36: 61 | B36: Z15099 | C36: 26517 | D36: North | E36: Punjab | F36: Mohali | G36: Collection & Repossession Agency | H36: Excel Agencies - Mohali | I36: Pawandeep Singh | J36: Pawandeep Singh / Pardeep Kumar/Prince Aneja/Sukhdev Chabbra/Tarandeep Singh | K36: Plot No 259,Phase Viii B,Industrial Focal Point,Sas Nagar, Mohali - 160062 | L36: 0172-4605355,4605245,0181-4608882,0161-4648632 | M36: 0172-4605355,4605245,0181-4608882,0161-4648632,9914141900,6280449688,9872074864,9646689689,7087344321,7986600380,6239609030,9779282827,7888714695,0172-5090526 | N36: 9914141900,9988210298,9317575751 | O36: ;excelbat@yahoo.co.in; excelyes9@gmail.com;exceljal.yesbank@gmail.com;excel.yesbankchd@gmail.com ; excel.yesbank56@gmail.com; excel2019@excelagencies.com | P36: NA | Q36: ANDPS3022N | S36: 03ANDPS3022N1Z2 | V36: YES BANK LIMITED | X36: Properitoryship | Y36: Active | Z36: 43579 | AA36: 43579 | AD36: Address addition details received on 16th Aug,Mohal add change req reced in Oct21. | AE36: 26517 | AF36: Excel Agencies | AG36: 1051 | AH36: 1002 | AI36: 925 | AJ36: 2978 | AL36: Allocaton given by Collection agency | AM36: Eligible for audit | AN36: KGAC | AO36: Ashutosh Gupta | AP36: Plot No 259,Phase Viii B,Industrial Focal Point,Sas Nagar, Mohali - 160062 | AQ36: Audited | AR36: NA | AT36: Dimple | AU36: Pawan Kumar | AV36: 9582917652 | AW36: 46123 | AX36: Kumar Gaurav Agarwal & company | AY36: Mohali | AZ36: Punjab | BA36: PSE6777607, JBE6662016, SGE6771981, SKE6776527, JSE6784665, KDE6778345, SCE6758746 | BB36: Pramod Sankhala, Jaspreet Bhathal, Sahil Gorsi, Sunil Kumar , Jagmohan Singh, Kailash Devanda, Sunil Choudhary | BC36: Ashutosh Gupta | BD36: Excel Agencies - Mohali | BE36: Excel Agencies - Mohali - Punjab | BF36: Excel Agencies - Mohali_Collection Agency_Punjab
A37: 183 | B37: Z16131 | C37: 25788 | D37: East | E37: West Bengal | F37: Kolkata | G37: Repossession Agency | H37: Bharat Repossession Unit | I37: Biswajit Dey | J37: Biswajit Dey | K37: 11, Bandhab Nagar, P.O + P.S – Belgharia, West Bengal, Kolkata - 700056 | L37: 9836671180 | M37: 9836671180,8981066924 | N37: 8961166923 | O37: biswajitdeyrepo@gmail.com; Brubd2000@yahoo.com | P37: NA | Q37: AKJPD5143L | R37: AKJPD5143LSD001 | S37: 19AKJPD5143L1ZY | U37: 076085800000011 | V37: YES BANK LIMITED | W37: OPENED | X37: Properitoryship | Y37: Active | Z37: 42588 | AA37: 42576 | AE37: 25788 | AF37: Bharat Repossession Unit | AG37: NA | AH37: NA | AI37: NA | AJ37: NA | AK37: 4 | AL37: Allocaton given by Repo agency | AM37: Eligible for audit | AN37: KGAC | AO37: #N/A | AP37: 11, Bandhab Nagar, P.O + P.S – Belgharia, West Bengal, Kolkata - 700056 | AQ37: Audited | AR37: NA | AT37: Sanjeev Chakraborty | AU37: Vikky Kumar | AV37: 9354241930 | AW37: 46119 | AX37: Kumar Gaurav Agarwal & company | AY37: Kolkata | AZ37: West Bengal | BA37: NA | BB37: Arindam Sarkar, Priyanka Mondal, Deepak Singh, Imran Elahi, Sachin Bharti, Sudip ManAmit Ranjan Singh, Suryakanta Jena | BC37: Subhasis Banerjee, Biswarup Ghosh | BD37: Bharat Repossession Unit | BE37: Bharat Repossession Unit - Kolkata - West Bengal | BF37: Bharat Repossession Unit_Collection Agency_Kolkata_West Bengal | BG37: Bharat Repossession Unit_Repo Agency_Kolkata_West Bengal
A38: 155 | B38: Z16778 | C38: 25428 | D38: North | E38: Rajasthan | F38: Ajmer | G38: Collection/Pickup/Repo Agency | H38: F K Associates | I38: Farid Khan | J38: Farid Khan | K38: 1St Floor Swami Complex, India Motor Circle Ajmer | L38: 0145-2427748 | M38: 0145-2427748,7725943164,9928754482,8078644514,9829070500 | N38: 9829070500,John,Bill,maker-,9772888871 | O38: fkassociate@yahoo.co.in; farid.khan.vendor@yesbank.in | P38: fkassociate788@gmail.com | Q38: AFDPK6193C | R38: ST/AJM/AJM/301/BAS/2005 | S38: 08AFDPK6193C1ZI | V38: YES BANK LIMITED | X38: Properitoryship | Y38: Active | Z38: 42147 | AA38: 42875 | AE38: 25428 | AF38: F K Associates | AG38: 432 | AH38: 409 | AI38: 393 | AJ38: 1234 | AL38: Allocaton given by Collection & Repossession | AM38: Eligible for audit | AN38: KGAC | AO38: Ashutosh Gupta | AP38: 1St Floor Swami Complex, India Motor Circle Ajmer | AQ38: Audited | AR38: Audited for Collection Only, as no activity of repossession are done for the audit quarter | AT38: Akash Kushwah / 7725943164 | AU38: Akash Sharma | AV38: 7688959606 | AW38: 46123 | AX38: Kumar Gaurav Agarwal & company | AY38: Ajmer | AZ38: Rajasthan | BA38: YME6753113, AHE6782821, PSE6777607, RSE6771124, SCE6758746, MSE6781974 | BB38: Yasin Mohammed, Akram Hussain, Pramod Sankhala, Ranjan Solanki, Sunil Choudhary, Manish Shukla | BC38: Ashutosh Gupta , Kalpesh Raval, Saurabh Saroch | BD38: F K Associates | BE38: F K Associates - Ajmer - Rajasthan | BF38: F K Associates_Collection Agency_Ajmer_Rajasthan
A39: 38 | B39: NA | C39: 348998 | D39: North | E39: Delhi | F39: Delhi | G39: Collection & Repossession Agency | H39: Aim Associates | I39: Sanjay Sethi | J39: Sanjay Sethi | K39: 3E/6 Jhandewaln Extn New Delhi 110055 | L39: 01146142871, 43702304 | M39: 01146142871, 43702304 | N39: 9811006913 | O39: ysethi@aimsanjay.com | P39: NA | Q39: ALJPS1500R | R39: 0 | S39: 07ALJPS1500R1ZP | T39: 0 | U39: 0 | V39: ICICI BANK LIMITED | W39: 0 | X39: Proprietorship | Y39: Active | Z39: 45838 | AA39: 45838 | AB39: 0 | AC39: 0 | AD39: 0 | AE39: 348998 | AF39: Aim Associates | AG39: 172 | AH39: 181 | AI39: 138 | AJ39: 491 | AL39: Allocaton given by Collection agency | AM39: Eligible for audit | AN39: KGAC | AO39: Sameer Dhar | AP39: NA | AQ39: Not Audited | AR39: Audited on another address : 45 46 , 2nd floor , west guru angad nagar , laxmi nagar -110092 | AS39: NA | AT39: NA | AU39: NA | AV39: NA | AW39: NA | AX39: NA | AY39: Delhi | AZ39: Delhi | BA39: PGE6777921, NSE6771909 | BB39: Priyanka Guptarinder Singh | BC39: Sameer Dhar, Sanjeev Kumar | BD39: Aim Associates | BE39: NA | BF39: NA | BG39: NA
A40: 111 | B40: NA | C40: 351036 | D40: East | E40: West Bengal | F40: Nadia | G40: Collection & Repossession Agency | H40: Boundless Grow Up Private Limited | I40: Mithun Halder/Suparna Jana | J40: Mithun Halder/Suparna Jana | K40: New Kalipur, Bhatjangla, Ps-Kotwali, Krishnanagar, Nadia, Pin-741102. | L40: 9609095019 / 7872433133 | M40: 9609095019 / 7872433133 | N40: 9609095019 / 7872433133 | O40: Boundlessgrowuppvtltd@gmail.com | P40: NA | Q40: AAKCB8919J | S40: 19AAKCB8919J1Z1 | X40: Partnership | Y40: Active | Z40: 45875 | AA40: 45875 | AE40: 351036 | AF40: Boundless Grow UP PRIVATE LIMITED | AG40: NA | AH40: NA | AI40: NA | AJ40: NA | AK40: 2 | AL40: Allocaton given by Repo agency | AM40: Eligible for audit | AN40: KGAC | AO40: #N/A | AP40: New Kalipur, Bhatjangla, Ps-Kotwali, Krishnanagar, Nadia, Pin-741102. | AQ40: Audited | AR40: NA | AT40: Subir Sikdar | AU40: Pradeep | AV40: 8287823681 | AW40: 46120 | AX40: Kumar Gaurav Agarwal & company | AY40: Nadia | AZ40: West Bengal | BA40: NA | BB40: Priyanka Mondal, Sourabh Parihar | BC40: Subhasis Banerjee, Biswarup Ghosh | BD40: Boundless Grow Up Private Limited | BE40: Boundless Grow Up Private Limited - Nadia - West Bengal | BF40: Boundless Grow Up Private Limited_Collection Agency_Nadia_West Bengal | BG40: Boundless Grow Up Private Limited_Repo Agency_Nadia_West Bengal
...

Sheet Audited
