Workbook

Sheet Checklist
C2: Agency Code | D2: SY3001 | F2: Auditor Name | G2: Amit
C3: Agency Name | D3: Prime Stockyard | F3: Audit Date | G3: 18/06/2026
C4: Agency Address | D4: Xyz | F4: Collection Manager | G4: Pradeep
C5: Type of agency | D5: Collection & Repo Agency | F5: Agency Manager | G5: Pradeep
A7: Sr.No. | B7: Rating Category | C7: Short Segmentation | D7: Particular | E7: Final Score | F7: Compliance status (Yes / No) | G7: Observation | H7: Closing Meeting Comments | I7: Pending Status (Open/ Closed) | J7: Timelines for Non-Closure Point
A8: 1 | B8: Allocation Compliance | C8: Account to Collector Ratio – Not adequate | D8: Account to Collector Ratio – Stats need to be mentioned | E8: Only Observation Point | F8: Yes | G8: Observation recorded for checkpoint 1 during audit review. | H8: None
A9: 2 | B9: Allocation Compliance | C9: Not All cases allocated to agency CREs | D9: Check whether all the cases allocated to agency in being allocated to CRE. | E9: =IF(F9="Yes",2,"0") | F9: Yes | G9: Observation recorded for checkpoint 2 during audit review. | H9: None
A10: 3 | B10: Call recording | C10: Call recording facility | D10: Whether Call recording facility is available at the agency & is in working condition? Also, check whether all calls made to the customers via M collect App? | E10: =IF(F10="Yes",4,"0") | F10: Yes | G10: Observation recorded for checkpoint 3 during audit review. | H10: None
A11: 4 | B11: Call recording | C11: Call recording Storage/Maintenance | D11: Whether call recording data is maintained as per policy? Also, check whether agency has done calling via M Collect App? Whether 100% call recording is done and maintained by the agency & retrieved all sample calls provided during audit?(Dialler + M-Collect) | E11: =IF(F11="Yes",4,"0") | F11: Yes | G11: Observation recorded for checkpoint 4 during audit review. | H11: None
A12: 5 | B12: TCOC | C12: Telephone Etiquette not followed | D12: Whether telephone etiquette is followed in calls? Any Non Compliance as per code of conduct & TCOC also if any Misbehaviour observed in calls to be noted. | E12: =IF(F12="Yes",3,"0") | F12: Yes | G12: Observation recorded for checkpoint 5 during audit review. | H12: None
A13: 6 | B13: TCOC | C13: Pseudo names | D13: Check whether tele callers using pseudo names? | E13: =IF(F13="Yes",1,"0") | F13: Yes | G13: Observation recorded for checkpoint 6 during audit review. | H13: None
A14: 7 | B14: TCOC | C14: TCL Posters | D14: Whether the Code of Conduct posters/ Collections Dos and Don'ts/ any other communication displayed in the offices? | E14: =IF(F14="Yes",2,"0") | F14: No | G14: Observation recorded for checkpoint 7 during audit review. | H14: Corrective action required
A15: 8 | B15: TCOC | C15: TCOC training by TCL Collection Manager | D15: Whether all agents are trained on the Tata code of conduct and are well dressed while on field ? (Need to check the acknowledgement of the training given by CM) Authorisation Letter - Sign by Collection Manager must required with CRE's details | E15: =IF(F15="Yes",2,"0") | F15: Yes | G15: Observation recorded for checkpoint 8 during audit review. | H15: None
A16: 9 | B16: TCOC | C16: COC declaration from all Agents must be stored | D16: Collection agency need to be taken declaration on code of conduct from all CRE's and this must be stored. | E16: =IF(F16="Yes",2,"0") | F16: Yes | G16: Observation recorded for checkpoint 9 during audit review. | H16: None
A17: 10 | B17: Cash Collection | C17: Cash Collection limit of 2 Lacs breached | D17: - Whether agency CRE has collected cash more than Rs. 1.99 lacs at any point in time during the Emi Months? (Sum of collected amount to be checked as per Loan No./customer name) - PAN at the time of collecting cash more than Rs. 49k | E17: =IF(F17="Yes",2,"0") | F17: Yes | G17: Observation recorded for checkpoint 10 during audit review. | H17: None
A18: 11 | B18: Cash Collection | C18: Deposit delay seen during sample check | D18: Whether the agency ensures that collections deposited within the TAT?Is there any instance of delayed deposition (More than 2 Days), If so, how many such instances are there | E18: =IF(F18="Yes",4,"0") | F18: NA | G18: Observation recorded for checkpoint 11 during audit review. | H18: Not Applicable
A19: 12 | B19: Cash Collection | C19: Unauthorized transaction in customer account | D19: Unauthorized transaction in customer account, For Example-Payment done on behalf of Customer or accepting payment in CRE's personal account (GPay, Paytm or any other wallet/bank account). | E19: =IF(F19="Yes",3,"0") | F19: Yes | G19: Observation recorded for checkpoint 12 during audit review. | H19: None
A20: 13 | B20: Cash Collection | C20: Multiple Receipt with Multiple Pin Code | D20: M-Collect Receipts issuance data to be reviewed, in case any CRE issuing unrealistic no. of receipts, reasons to be check | E20: Only Observation Point | F20: Yes | G20: Observation recorded for checkpoint 13 during audit review. | H20: None
A21: 14 | B21: Cash Collection | C21: Receipts Issuance in Non Working Hours | D21: Any instance where M-Collect Receipt has been issued in Non-Working Hours | E21: =IF(F21="Yes",3,"0") | F21: No | G21: Observation recorded for checkpoint 14 during audit review. | H21: Corrective action required
A22: 15 | B22: Cash Collection | C22: Receipts issuance by other Agency | D22: Any Receipts issued by the agency which is not in allocation Or CM/ Off role are issuing receipts instead of same agency | E22: Only Observation Point | F22: Yes | G22: Observation recorded for checkpoint 15 during audit review. | H22: None
A23: 16 | B23: Cash Collection | C23: Customer payment not deposited to agency or TCL | D23: Any instances where the CRE collected the money from the customer but the same was not deposited In customer account/not deposited to agency/not deposited in TCL? | E23: =IF(F23="Yes",2,"0") | F23: Yes | G23: Observation recorded for checkpoint 16 during audit review. | H23: None
A24: 17 | B24: Data Security | C24: Agency system has no restrictions hence data may fall into wrong hands | D24: Whether agency has restricted access of Desktop / Laptops/ Emails are enabled? Check whether agency do not have access of USB/Floppy/CD drives/Google Drive/Cloud storage/share drive/WhatsApp/any data sharing application for data transfer? | E24: =IF(F24="Yes",3,"0") | F24: Yes | G24: Observation recorded for checkpoint 17 during audit review. | H24: None
A25: 18 | B25: Data Security | C25: Allocation files were not password protected | D25: Whether data shared through mail are password protected / appropriate security measures are adopted by agency? | E25: =IF(F25="Yes",2,"0") | F25: Yes | G25: Observation recorded for checkpoint 18 during audit review. | H25: None
A26: 19 | B26: Data Security | C26: Data is being shared on unregistered email ids | D26: Whether any mail containing financial institution's data sent to third party / unregistered mail Ids / unauthorized sharing? Customer Call/Chat on unauthorized channels like what's ap/Facebook or any other unauthorized mode of communication? In case agency using secondary mail id, it must be documented with TCL team. | E26: =IF(F26="Yes",3,"0") | F26: Yes | G26: Observation recorded for checkpoint 19 during audit review. | H26: None
A27: 20 | B27: Data Security | C27: Data purging is not being done – Old allocation files were available in agency's system | D27: Whether agency has purged data as per policy? | E27: =IF(F27="Yes",3,"0") | F27: Yes | G27: Observation recorded for checkpoint 20 during audit review. | H27: None
A28: 21 | B28: Data Security | C28: Data Retention | D28: Whether data has been retained at the agency's system and Email ID as per policy (T+3 months)? | E28: =IF(F28="Yes",2,"0") | F28: No | G28: Observation recorded for checkpoint 21 during audit review. | H28: Corrective action required
A29: 22 | B29: Data Security | C29: Agency system has no restrictions hence data may fall into wrong hands | D29: Check whether agency do not have access of any internal access tool like SFDC/DMS/Any other tool? | E29: =IF(F29="Yes",1,"0") | F29: NA | G29: Observation recorded for checkpoint 22 during audit review. | H29: Not Applicable
A30: 23 | B30: Data Security | C30: No exclusive system provided to TCL portfolio | D30: Whether separate/exclusive system, Place/work Station, Email ID and Manpower is provided? | E30: =IF(F30="Yes",3,"0") | F30: Yes | G30: Observation recorded for checkpoint 23 during audit review. | H30: None
A31: 24 | B31: Infra and others | C31: Current address is not updated to TCL | D31: Whether agency has updated address & other details in company records and, In case agency providing services in multiple locations to TCL Collection then it must be documented with TCL team. | E31: =IF(F31="Yes",1,"0") | F31: Yes | G31: Observation recorded for checkpoint 24 during audit review. | H31: None
A32: 25 | B32: Infra and others | C32: Not cooperated by agency during audit | D32: Whether full cooperation/complete & timely data was received from agency for completing audit? | E32: =IF(F32="Yes",1,"0") | F32: Yes | G32: Observation recorded for checkpoint 25 during audit review. | H32: None
A33: 26 | B33: Infra and others | C33: Vendor code not created | D33: Whether allocation for Collection cases as well for repossession cases given to the agency post vendor code creation only? | E33: =IF(F33="Yes",1,"0") | F33: Yes | G33: Observation recorded for checkpoint 26 during audit review. | H33: None
A34: 27 | B34: Infra and others | C34: Tata capital's name being used in agency office | D34: Has the agency made any reference to company's name on the his's name board & e-mail ? | E34: =IF(F34="Yes",1,"0") | F34: Yes | G34: Observation recorded for checkpoint 27 during audit review. | H34: None
A35: 28 | B35: Identity cards | C35: All CREs have valid ID Cards of TCL | D35: Whether all active CREs working for TCL portfolio having Digital ID Cards with them? Also, check whether any executive using unauthorized ID card while on field? | E35: =IF(F35="Yes",3,"0") | F35: No | G35: Observation recorded for checkpoint 28 during audit review. | H35: Corrective action required
A36: 29 | B36: Identity cards | C36: If assigned CRE resigned/terminated it is not communicated to TCL | D36: In case of resignation / termination of any executive whether it is communicated within TAT of 24 hours; (M-collect ID should be deactivated ) | E36: =IF(F36="Yes",2,"0") | F36: Yes | G36: Observation recorded for checkpoint 29 during audit review. | H36: None
A37: 30 | B37: Identity cards | C37: Not all CREs have M Collect ID's | D37: Whether all active CRE has M-collect ID in system? (M-collect should be active) Is there M-collect ID of any CRE being used by another CRE? | E37: =IF(F37="Yes",4,"0") | F37: Yes | G37: Observation recorded for checkpoint 30 during audit review. | H37: None
A38: 31 | B38: Identity cards | C38: PV report not available | D38: Whether all agency executives, backends, Supervisor,Proprieter, CRE's Police verification are vetted & no negative Police verification CRE's are working at the agency? | E38: =IF(F38="Yes",2,"0") | F38: Yes | G38: Observation recorded for checkpoint 31 during audit review. | H38: None
A39: 32 | B39: Repossession Process | C39: Expired repo kit used/NCM Approval not taken before repossession | D39: Whether agency has returned all unused repo kits within 5 days of expiry? Whether NCM approval taken before initiating repossession on email/System? | E39: Only Observation Point | F39: Yes | G39: Observation recorded for checkpoint 32 during audit review. | H39: None
A40: 33 | B40: Repossession Process | C40: Indemnity bond and newspaper publication not issued after repo kit loss | D40: Whether FIR, indemnity bond on stamp paper & Newspaper cut-out of published Notice for Loss / theft of repo kit is submitted by Agency as per format in case of lost/stolen repo kit & updated in repo kit tracker ? | E40: =IF(F40="Yes",1,"0") | F40: NA | G40: Observation recorded for checkpoint 33 during audit review. | H40: Not Applicable
A41: 34 | B41: Repossession Process | C41: Repossession done without valid Repo Kit | D41: Check whether any Repo done without valid repo kit? The repo date and repo kit issuance date should be validated. | E41: =IF(F41="Yes",1,"0") | F41: Yes | G41: Observation recorded for checkpoint 34 during audit review. | H41: None
A42: 35 | B42: Repossession Process | C42: Repo Kit Return Delay by agency | D42: Whether possession kit along with all the documents are to be dispatched to the Central team/Branch within 2 business days from the time of deposition of repossessed asset in the yard? | E42: =IF(F42="Yes",2,"0") | F42: No | G42: Observation recorded for checkpoint 35 during audit review. | H42: Corrective action required
...

Sheet Score Parameters
A1: S. No. | B1: Particulars | C1: Key Points | D1: Weightage | E1: Actual | F1: Percentage
A2: 1 | B2: Allocation Compliance | C2: =COUNTIF(Checklist!$B$7:$B$77,B2) | D2: 2 | E2: =SUMIF(Checklist!$B$7:$B$68,'Score Parameters'!B2,Checklist!$E$7:$E$68) | F2: =IFERROR(E2/D2,"-")
A3: 2 | B3: Call recording | C3: =COUNTIF(Checklist!$B$7:$B$77,B3) | D3: 8 | E3: =SUMIF(Checklist!$B$7:$B$68,'Score Parameters'!B3,Checklist!$E$7:$E$68) | F3: =IFERROR(E3/D3,"-")
A4: 3 | B4: TCOC | C4: =COUNTIF(Checklist!$B$7:$B$77,B4) | D4: 10 | E4: =SUMIF(Checklist!$B$7:$B$68,'Score Parameters'!B4,Checklist!$E$7:$E$68) | F4: =IFERROR(E4/D4,"-")
A5: 4 | B5: Cash Collection | C5: =COUNTIF(Checklist!$B$7:$B$77,B5) | D5: 14 | E5: =SUMIF(Checklist!$B$7:$B$68,'Score Parameters'!B5,Checklist!$E$7:$E$68) | F5: =IFERROR(E5/D5,"-")
A6: 5 | B6: Data Security | C6: =COUNTIF(Checklist!$B$7:$B$77,B6) | D6: 17 | E6: =SUMIF(Checklist!$B$7:$B$68,'Score Parameters'!B6,Checklist!$E$7:$E$68) | F6: =IFERROR(E6/D6,"-")
A7: 6 | B7: Infra and others | C7: =COUNTIF(Checklist!$B$7:$B$77,B7) | D7: 4 | E7: =SUMIF(Checklist!$B$7:$B$68,'Score Parameters'!B7,Checklist!$E$7:$E$68) | F7: =IFERROR(E7/D7,"-")
A8: 7 | B8: Identity cards | C8: =COUNTIF(Checklist!$B$7:$B$77,B8) | D8: 11 | E8: =SUMIF(Checklist!$B$7:$B$68,'Score Parameters'!B8,Checklist!$E$7:$E$68) | F8: =IFERROR(E8/D8,"-")
A9: 8 | B9: Repossession Process | C9: =COUNTIF(Checklist!$B$7:$B$77,B9) | D9: 15 | E9: =SUMIF(Checklist!$B$7:$B$68,'Score Parameters'!B9,Checklist!$E$7:$E$68) | F9: =IFERROR(E9/D9,"-")
A10: 9 | B10: Record Management | C10: =COUNTIF(Checklist!$B$7:$B$77,B10) | D10: 17 | E10: =SUMIF(Checklist!$B$7:$B$68,'Score Parameters'!B10,Checklist!$E$7:$E$68) | F10: =IFERROR(E10/D10,"-")
A11: 10 | B11: Settlement Compliance | C11: =COUNTIF(Checklist!$B$7:$B$77,B11) | D11: 2 | E11: =SUMIF(Checklist!$B$7:$B$68,'Score Parameters'!B11,Checklist!$E$7:$E$68) | F11: =IFERROR(E11/D11,"-")
A12: 11 | B12: Miscellaneous | C12: =COUNTIF(Checklist!$B$7:$B$77,B12) | D12: 0 | E12: =SUMIF(Checklist!$B$7:$B$68,'Score Parameters'!B12,Checklist!$E$7:$E$68) | F12: =IFERROR(E12/D12,"-")
B13: Total | C13: =SUM(C2:C12) | D13: =SUM(D2:D12) | E13: =SUM(E2:E12) | F13: =E13/D13
A14: FINAL RATING | F14: {=_xlfn.IFS(F13>=80%,B17,F13>=70%,B18,F13>=60%,B19,F13>=50%,B20,F13<=49%,B21)}
B16: Rating | C16: Scoring Segmentation
B17: A | C17: >=80
B18: B | C18: >=70 and <=79
B19: C | C19: >=60 and <=69
B20: D | C20: >=50 and <=59
B21: E | C21: <=49

Sheet Supporting
A1: Observation
